Workbook
Name GZ: Table58[GZ]
Name Orden: Table1[Orden]
Name Periodo: Table6[Periodo]
Name Tipo_de_Servicio: Table2[Tipo de Servicio]
Name TipoServicioColumn: Table2[[#All],[Servicio]]
Name TipoServicioStar: Table2[[#Headers],[Servicio]]

Sheet Caratula
A1: MttoEF
B2: Solicitud -Pago a Proveedores de Servicio - Semanal
B9: Mantenimiento - Equipo Frío | D9: Instalación / Retiro - Equipo Frío
C15: Número Proveedor
C16: GZ | D16: NUEVO LEON
C17: Periodo - Semana | D17: S1926
C19: Inicio | D19: Fin
C20: =VLOOKUP(D17,Catalogo!L:N,2,0) -> 46147 | D20: =VLOOKUP(D17,Catalogo!L:N,3,0) -> 46153
F21: v1.0

Sheet Registro Ordenes
A1: Proveedor | B1: GZ | C1: Periodo | D1: SelGZ | E1: Tipo de Servicio | F1: PEP | G1: Nombre el PEP | H1: Aviso | I1: Orden | J1: Cliente | K1: Equipo | L1: Serie | M1: Fecha Cierre | N1: Costo Servicio | O1: Refacciones | P1: Total | Q1: Comentarios
A2: =IF(Table1[[#This Row],[Tipo de Servicio]]="","",Caratula!$D$15) -> 0 | B2: =IF(Table1[[#This Row],[Tipo de Servicio]]="","",Caratula!$D$16) -> TAMAULIPAS SUR-VER NTE | C2: =IF(Table1[[#This Row],[Tipo de Servicio]]="","",Caratula!$D$17) -> S1926 | D2: =IF(ISBLANK(Table1[[#This Row],[Tipo de Servicio]]),"",Caratula!$D$16) -> TAMAULIPAS SUR-VER NTE | E2: COMPRA TANQUE CO2 - BARRIL | F2: =_xlfn.XLOOKUP(Table1[[#This Row],[SelGZ]]&Table1[[#This Row],[Tipo de Servicio]],CatPEP!A:A,CatPEP!C:C,"") | G2: =_xlfn.XLOOKUP(Table1[[#This Row],[PEP]],CatPEP!C:C,CatPEP!D:D,"") | O2: =SUMIF('Registro Refacciones'!B:B, I2, 'Registro Refacciones'!I:I) -> 0 | P2: =Table1[[#This Row],[Costo Servicio]]+Table1[[#This Row],[Refacciones]] -> 0
A3: =IF(Table1[[#This Row],[Tipo de Servicio]]="","",Caratula!$D$15) -> 0 | B3: =IF(Table1[[#This Row],[Tipo de Servicio]]="","",Caratula!$D$16) -> TAMAULIPAS SUR-VER NTE | C3: =IF(Table1[[#This Row],[Tipo de Servicio]]="","",Caratula!$D$17) -> S1926 | D3: =IF(ISBLANK(Table1[[#This Row],[Tipo de Servicio]]),"",Caratula!$D$16) -> TAMAULIPAS SUR-VER NTE | E3: MTTO CORRECTIVO RUTA - BARRIL | F3: =_xlfn.XLOOKUP(Table1[[#This Row],[SelGZ]]&Table1[[#This Row],[Tipo de Servicio]],CatPEP!A:A,CatPEP!C:C,"") -> M/MXCM/26/CG1J/C2/815/02 | G3: =_xlfn.XLOOKUP(Table1[[#This Row],[PEP]],CatPEP!C:C,CatPEP!D:D,"") -> MTTO BARRIL | O3: =SUMIF('Registro Refacciones'!B:B, I3, 'Registro Refacciones'!I:I) -> 0 | P3: =Table1[[#This Row],[Costo Servicio]]+Table1[[#This Row],[Refacciones]] -> 0
A4: =IF(Table1[[#This Row],[Tipo de Servicio]]="","",Caratula!$D$15) -> 0 | B4: =IF(Table1[[#This Row],[Tipo de Servicio]]="","",Caratula!$D$16) -> TAMAULIPAS SUR-VER NTE | C4: =IF(Table1[[#This Row],[Tipo de Servicio]]="","",Caratula!$D$17) -> S1926 | D4: =IF(ISBLANK(Table1[[#This Row],[Tipo de Servicio]]),"",Caratula!$D$16) -> TAMAULIPAS SUR-VER NTE | E4: FLETE MOV GZ A GZ - ENFRIADOR | F4: =_xlfn.XLOOKUP(Table1[[#This Row],[SelGZ]]&Table1[[#This Row],[Tipo de Servicio]],CatPEP!A:A,CatPEP!C:C,"") -> M/MXCM/26/GA6B/C6/815/03 | G4: =_xlfn.XLOOKUP(Table1[[#This Row],[PEP]],CatPEP!C:C,CatPEP!D:D,"") -> MOVIMIENTOS FLETES NAC | O4: =SUMIF('Registro Refacciones'!B:B, I4, 'Registro Refacciones'!I:I) -> 0 | P4: =Table1[[#This Row],[Costo Servicio]]+Table1[[#This Row],[Refacciones]] -> 0
A5: =IF(Table1[[#This Row],[Tipo de Servicio]]="","",Caratula!$D$15) | B5: =IF(Table1[[#This Row],[Tipo de Servicio]]="","",Caratula!$D$16) | C5: =IF(Table1[[#This Row],[Tipo de Servicio]]="","",Caratula!$D$17) | D5: =IF(ISBLANK(Table1[[#This Row],[Tipo de Servicio]]),"",Caratula!$D$16) | F5: =_xlfn.XLOOKUP(Table1[[#This Row],[SelGZ]]&Table1[[#This Row],[Tipo de Servicio]],CatPEP!A:A,CatPEP!C:C,"") | G5: =_xlfn.XLOOKUP(Table1[[#This Row],[PEP]],CatPEP!C:C,CatPEP!D:D,"") | O5: =SUMIF('Registro Refacciones'!B:B, I5, 'Registro Refacciones'!I:I) -> 0 | P5: =Table1[[#This Row],[Costo Servicio]]+Table1[[#This Row],[Refacciones]] -> 0
A6: =IF(Table1[[#This Row],[Tipo de Servicio]]="","",Caratula!$D$15) -> 0 | B6: =IF(Table1[[#This Row],[Tipo de Servicio]]="","",Caratula!$D$16) -> TAMAULIPAS SUR-VER NTE | C6: =IF(Table1[[#This Row],[Tipo de Servicio]]="","",Caratula!$D$17) -> S1926 | D6: =IF(ISBLANK(Table1[[#This Row],[Tipo de Servicio]]),"",Caratula!$D$16) -> TAMAULIPAS SUR-VER NTE | E6: FLETES-TALLER - MOVIMIENTOS | F6: =_xlfn.XLOOKUP(Table1[[#This Row],[SelGZ]]&Table1[[#This Row],[Tipo de Servicio]],CatPEP!A:A,CatPEP!C:C,"") -> M/MXCM/26/CG1J/C2/815/01 | G6: =_xlfn.XLOOKUP(Table1[[#This Row],[PEP]],CatPEP!C:C,CatPEP!D:D,"") -> MOVIMIENTOS | O6: =SUMIF('Registro Refacciones'!B:B, I6, 'Registro Refacciones'!I:I) -> 0 | P6: =Table1[[#This Row],[Costo Servicio]]+Table1[[#This Row],[Refacciones]] -> 0
A7: =IF(Table1[[#This Row],[Tipo de Servicio]]="","",Caratula!$D$15) | B7: =IF(Table1[[#This Row],[Tipo de Servicio]]="","",Caratula!$D$16) | C7: =IF(Table1[[#This Row],[Tipo de Servicio]]="","",Caratula!$D$17) | D7: =IF(ISBLANK(Table1[[#This Row],[Tipo de Servicio]]),"",Caratula!$D$16) | F7: =_xlfn.XLOOKUP(Table1[[#This Row],[SelGZ]]&Table1[[#This Row],[Tipo de Servicio]],CatPEP!A:A,CatPEP!C:C,"") | G7: =_xlfn.XLOOKUP(Table1[[#This Row],[PEP]],CatPEP!C:C,CatPEP!D:D,"") | O7: =SUMIF('Registro Refacciones'!B:B, I7, 'Registro Refacciones'!I:I) -> 0 | P7: =Table1[[#This Row],[Costo Servicio]]+Table1[[#This Row],[Refacciones]] -> 0
A8: =IF(Table1[[#This Row],[Tipo de Servicio]]="","",Caratula!$D$15) -> 0 | B8: =IF(Table1[[#This Row],[Tipo de Servicio]]="","",Caratula!$D$16) -> TAMAULIPAS SUR-VER NTE | C8: =IF(Table1[[#This Row],[Tipo de Servicio]]="","",Caratula!$D$17) -> S1926 | D8: =IF(ISBLANK(Table1[[#This Row],[Tipo de Servicio]]),"",Caratula!$D$16) -> TAMAULIPAS SUR-VER NTE | E8: FLETES-TALLER - MOVIMIENTOS | F8: =_xlfn.XLOOKUP(Table1[[#This Row],[SelGZ]]&Table1[[#This Row],[Tipo de Servicio]],CatPEP!A:A,CatPEP!C:C,"") -> M/MXCM/26/CG1J/C2/815/01 | G8: =_xlfn.XLOOKUP(Table1[[#This Row],[PEP]],CatPEP!C:C,CatPEP!D:D,"") -> MOVIMIENTOS | O8: =SUMIF('Registro Refacciones'!B:B, I8, 'Registro Refacciones'!I:I) -> 0 | P8: =Table1[[#This Row],[Costo Servicio]]+Table1[[#This Row],[Refacciones]] -> 0
A9: =IF(Table1[[#This Row],[Tipo de Servicio]]="","",Caratula!$D$15) -> 0 | B9: =IF(Table1[[#This Row],[Tipo de Servicio]]="","",Caratula!$D$16) -> TAMAULIPAS SUR-VER NTE | C9: =IF(Table1[[#This Row],[Tipo de Servicio]]="","",Caratula!$D$17) -> S1926 | D9: =IF(ISBLANK(Table1[[#This Row],[Tipo de Servicio]]),"",Caratula!$D$16) -> TAMAULIPAS SUR-VER NTE | E9: INSTALACION - ENFRIADOR | F9: =_xlfn.XLOOKUP(Table1[[#This Row],[SelGZ]]&Table1[[#This Row],[Tipo de Servicio]],CatPEP!A:A,CatPEP!C:C,"") -> M/MXCM/26/CG1J/C2/815/01 | G9: =_xlfn.XLOOKUP(Table1[[#This Row],[PEP]],CatPEP!C:C,CatPEP!D:D,"") -> MOVIMIENTOS | I9: 456 | N9: 130 | O9: =SUMIF('Registro Refacciones'!B:B, I9, 'Registro Refacciones'!I:I) -> 0 | P9: =Table1[[#This Row],[Costo Servicio]]+Table1[[#This Row],[Refacciones]] -> 130
A10: =IF(Table1[[#This Row],[Tipo de Servicio]]="","",Caratula!$D$15) | B10: =IF(Table1[[#This Row],[Tipo de Servicio]]="","",Caratula!$D$16) | C10: =IF(Table1[[#This Row],[Tipo de Servicio]]="","",Caratula!$D$17) | D10: =IF(ISBLANK(Table1[[#This Row],[Tipo de Servicio]]),"",Caratula!$D$16) | F10: =_xlfn.XLOOKUP(Table1[[#This Row],[SelGZ]]&Table1[[#This Row],[Tipo de Servicio]],CatPEP!A:A,CatPEP!C:C,"") | G10: =_xlfn.XLOOKUP(Table1[[#This Row],[PEP]],CatPEP!C:C,CatPEP!D:D,"") | O10: =SUMIF('Registro Refacciones'!B:B, I10, 'Registro Refacciones'!I:I) -> 0 | P10: =Table1[[#This Row],[Costo Servicio]]+Table1[[#This Row],[Refacciones]] -> 0
A11: =IF(Table1[[#This Row],[Tipo de Servicio]]="","",Caratula!$D$15) | B11: =IF(Table1[[#This Row],[Tipo de Servicio]]="","",Caratula!$D$16) | C11: =IF(Table1[[#This Row],[Tipo de Servicio]]="","",Caratula!$D$17) | D11: =IF(ISBLANK(Table1[[#This Row],[Tipo de Servicio]]),"",Caratula!$D$16) | F11: =_xlfn.XLOOKUP(Table1[[#This Row],[SelGZ]]&Table1[[#This Row],[Tipo de Servicio]],CatPEP!A:A,CatPEP!C:C,"") | G11: =_xlfn.XLOOKUP(Table1[[#This Row],[PEP]],CatPEP!C:C,CatPEP!D:D,"") | O11: =SUMIF('Registro Refacciones'!B:B, I11, 'Registro Refacciones'!I:I) -> 0 | P11: =Table1[[#This Row],[Costo Servicio]]+Table1[[#This Row],[Refacciones]] -> 0
A12: =IF(Table1[[#This Row],[Tipo de Servicio]]="","",Caratula!$D$15) | B12: =IF(Table1[[#This Row],[Tipo de Servicio]]="","",Caratula!$D$16) | C12: =IF(Table1[[#This Row],[Tipo de Servicio]]="","",Caratula!$D$17) | D12: =IF(ISBLANK(Table1[[#This Row],[Tipo de Servicio]]),"",Caratula!$D$16) | F12: =_xlfn.XLOOKUP(Table1[[#This Row],[SelGZ]]&Table1[[#This Row],[Tipo de Servicio]],CatPEP!A:A,CatPEP!C:C,"") | G12: =_xlfn.XLOOKUP(Table1[[#This Row],[PEP]],CatPEP!C:C,CatPEP!D:D,"") | O12: =SUMIF('Registro Refacciones'!B:B, I12, 'Registro Refacciones'!I:I) -> 0 | P12: =Table1[[#This Row],[Costo Servicio]]+Table1[[#This Row],[Refacciones]] -> 0
A13: =IF(Table1[[#This Row],[Tipo de Servicio]]="","",Caratula!$D$15) | B13: =IF(Table1[[#This Row],[Tipo de Servicio]]="","",Caratula!$D$16) | C13: =IF(Table1[[#This Row],[Tipo de Servicio]]="","",Caratula!$D$17) | D13: =IF(ISBLANK(Table1[[#This Row],[Tipo de Servicio]]),"",Caratula!$D$16) | F13: =_xlfn.XLOOKUP(Table1[[#This Row],[SelGZ]]&Table1[[#This Row],[Tipo de Servicio]],CatPEP!A:A,CatPEP!C:C,"") | G13: =_xlfn.XLOOKUP(Table1[[#This Row],[PEP]],CatPEP!C:C,CatPEP!D:D,"") | O13: =SUMIF('Registro Refacciones'!B:B, I13, 'Registro Refacciones'!I:I) -> 0 | P13: =Table1[[#This Row],[Costo Servicio]]+Table1[[#This Row],[Refacciones]] -> 0
A14: =IF(Table1[[#This Row],[Tipo de Servicio]]="","",Caratula!$D$15) | B14: =IF(Table1[[#This Row],[Tipo de Servicio]]="","",Caratula!$D$16) | C14: =IF(Table1[[#This Row],[Tipo de Servicio]]="","",Caratula!$D$17) | D14: =IF(ISBLANK(Table1[[#This Row],[Tipo de Servicio]]),"",Caratula!$D$16) | F14: =_xlfn.XLOOKUP(Table1[[#This Row],[SelGZ]]&Table1[[#This Row],[Tipo de Servicio]],CatPEP!A:A,CatPEP!C:C,"") | G14: =_xlfn.XLOOKUP(Table1[[#This Row],[PEP]],CatPEP!C:C,CatPEP!D:D,"") | O14: =SUMIF('Registro Refacciones'!B:B, I14, 'Registro Refacciones'!I:I) -> 0 | P14: =Table1[[#This Row],[Costo Servicio]]+Table1[[#This Row],[Refacciones]] -> 0
A15: =IF(Table1[[#This Row],[Tipo de Servicio]]="","",Caratula!$D$15) | B15: =IF(Table1[[#This Row],[Tipo de Servicio]]="","",Caratula!$D$16) | C15: =IF(Table1[[#This Row],[Tipo de Servicio]]="","",Caratula!$D$17) | D15: =IF(ISBLANK(Table1[[#This Row],[Tipo de Servicio]]),"",Caratula!$D$16) | F15: =_xlfn.XLOOKUP(Table1[[#This Row],[SelGZ]]&Table1[[#This Row],[Tipo de Servicio]],CatPEP!A:A,CatPEP!C:C,"") | G15: =_xlfn.XLOOKUP(Table1[[#This Row],[PEP]],CatPEP!C:C,CatPEP!D:D,"") | O15: =SUMIF('Registro Refacciones'!B:B, I15, 'Registro Refacciones'!I:I) -> 0 | P15: =Table1[[#This Row],[Costo Servicio]]+Table1[[#This Row],[Refacciones]] -> 0
A16: =IF(Table1[[#This Row],[Tipo de Servicio]]="","",Caratula!$D$15) | B16: =IF(Table1[[#This Row],[Tipo de Servicio]]="","",Caratula!$D$16) | C16: =IF(Table1[[#This Row],[Tipo de Servicio]]="","",Caratula!$D$17) | D16: =IF(ISBLANK(Table1[[#This Row],[Tipo de Servicio]]),"",Caratula!$D$16) | F16: =_xlfn.XLOOKUP(Table1[[#This Row],[SelGZ]]&Table1[[#This Row],[Tipo de Servicio]],CatPEP!A:A,CatPEP!C:C,"") | G16: =_xlfn.XLOOKUP(Table1[[#This Row],[PEP]],CatPEP!C:C,CatPEP!D:D,"") | O16: =SUMIF('Registro Refacciones'!B:B, I16, 'Registro Refacciones'!I:I) -> 0 | P16: =Table1[[#This Row],[Costo Servicio]]+Table1[[#This Row],[Refacciones]] -> 0
A17: =IF(Table1[[#This Row],[Tipo de Servicio]]="","",Caratula!$D$15) | B17: =IF(Table1[[#This Row],[Tipo de Servicio]]="","",Caratula!$D$16) | C17: =IF(Table1[[#This Row],[Tipo de Servicio]]="","",Caratula!$D$17) | D17: =IF(ISBLANK(Table1[[#This Row],[Tipo de Servicio]]),"",Caratula!$D$16) | F17: =_xlfn.XLOOKUP(Table1[[#This Row],[SelGZ]]&Table1[[#This Row],[Tipo de Servicio]],CatPEP!A:A,CatPEP!C:C,"") | G17: =_xlfn.XLOOKUP(Table1[[#This Row],[PEP]],CatPEP!C:C,CatPEP!D:D,"") | O17: =SUMIF('Registro Refacciones'!B:B, I17, 'Registro Refacciones'!I:I) -> 0 | P17: =Table1[[#This Row],[Costo Servicio]]+Table1[[#This Row],[Refacciones]] -> 0
A18: =IF(Table1[[#This Row],[Tipo de Servicio]]="","",Caratula!$D$15) | B18: =IF(Table1[[#This Row],[Tipo de Servicio]]="","",Caratula!$D$16) | C18: =IF(Table1[[#This Row],[Tipo de Servicio]]="","",Caratula!$D$17) | D18: =IF(ISBLANK(Table1[[#This Row],[Tipo de Servicio]]),"",Caratula!$D$16) | F18: =_xlfn.XLOOKUP(Table1[[#This Row],[SelGZ]]&Table1[[#This Row],[Tipo de Servicio]],CatPEP!A:A,CatPEP!C:C,"") | G18: =_xlfn.XLOOKUP(Table1[[#This Row],[PEP]],CatPEP!C:C,CatPEP!D:D,"") | O18: =SUMIF('Registro Refacciones'!B:B, I18, 'Registro Refacciones'!I:I) -> 0 | P18: =Table1[[#This Row],[Costo Servicio]]+Table1[[#This Row],[Refacciones]] -> 0
A19: =IF(Table1[[#This Row],[Tipo de Servicio]]="","",Caratula!$D$15) | B19: =IF(Table1[[#This Row],[Tipo de Servicio]]="","",Caratula!$D$16) | C19: =IF(Table1[[#This Row],[Tipo de Servicio]]="","",Caratula!$D$17) | D19: =IF(ISBLANK(Table1[[#This Row],[Tipo de Servicio]]),"",Caratula!$D$16) | F19: =_xlfn.XLOOKUP(Table1[[#This Row],[SelGZ]]&Table1[[#This Row],[Tipo de Servicio]],CatPEP!A:A,CatPEP!C:C,"") | G19: =_xlfn.XLOOKUP(Table1[[#This Row],[PEP]],CatPEP!C:C,CatPEP!D:D,"") | O19: =SUMIF('Registro Refacciones'!B:B, I19, 'Registro Refacciones'!I:I) -> 0 | P19: =Table1[[#This Row],[Costo Servicio]]+Table1[[#This Row],[Refacciones]] -> 0
A20: =IF(Table1[[#This Row],[Tipo de Servicio]]="","",Caratula!$D$15) | B20: =IF(Table1[[#This Row],[Tipo de Servicio]]="","",Caratula!$D$16) | C20: =IF(Table1[[#This Row],[Tipo de Servicio]]="","",Caratula!$D$17) | D20: =IF(ISBLANK(Table1[[#This Row],[Tipo de Servicio]]),"",Caratula!$D$16) | F20: =_xlfn.XLOOKUP(Table1[[#This Row],[SelGZ]]&Table1[[#This Row],[Tipo de Servicio]],CatPEP!A:A,CatPEP!C:C,"") | G20: =_xlfn.XLOOKUP(Table1[[#This Row],[PEP]],CatPEP!C:C,CatPEP!D:D,"") | O20: =SUMIF('Registro Refacciones'!B:B, I20, 'Registro Refacciones'!I:I) -> 0 | P20: =Table1[[#This Row],[Costo Servicio]]+Table1[[#This Row],[Refacciones]] -> 0
A21: =IF(Table1[[#This Row],[Tipo de Servicio]]="","",Caratula!$D$15) | B21: =IF(Table1[[#This Row],[Tipo de Servicio]]="","",Caratula!$D$16) | C21: =IF(Table1[[#This Row],[Tipo de Servicio]]="","",Caratula!$D$17) | D21: =IF(ISBLANK(Table1[[#This Row],[Tipo de Servicio]]),"",Caratula!$D$16) | F21: =_xlfn.XLOOKUP(Table1[[#This Row],[SelGZ]]&Table1[[#This Row],[Tipo de Servicio]],CatPEP!A:A,CatPEP!C:C,"") | G21: =_xlfn.XLOOKUP(Table1[[#This Row],[PEP]],CatPEP!C:C,CatPEP!D:D,"") | O21: =SUMIF('Registro Refacciones'!B:B, I21, 'Registro Refacciones'!I:I) -> 0 | P21: =Table1[[#This Row],[Costo Servicio]]+Table1[[#This Row],[Refacciones]] -> 0
... A1001: =IF(Table1[[#This Row],[Tipo de Servicio]]="","",Caratula!$D$15) | B1001: =IF(Table1[[#This Row],[Tipo de Servicio]]="","",Caratula!$D$16) | C1001: =IF(Table1[[#This Row],[Tipo de Servicio]]="","",Caratula!$D$17) | D1001: =IF(ISBLANK(Table1[[#This Row],[Tipo de Servicio]]),"",Caratula!$D$16) | F1001: =_xlfn.XLOOKUP(Table1[[#This Row],[SelGZ]]&Table1[[#This Row],[Tipo de Servicio]],CatPEP!A:A,CatPEP!C:C,"") | G1001: =_xlfn.XLOOKUP(Table1[[#This Row],[PEP]],CatPEP!C:C,CatPEP!D:D,"") | O1001: =SUMIF('Registro Refacciones'!B:B, I1001, 'Registro Refacciones'!I:I) -> 0 | P1001: =Table1[[#This Row],[Costo Servicio]]+Table1[[#This Row],[Refacciones]] -> 0

Sheet Registro Refacciones
A1: SelGZ | B1: Orden de Servicio | C1: Equipo | D1: PEP | E1: Nombre PEP | F1: Refacción | G1: Cantidad | H1: Precio Unitario | I1: Precio Total
A2: =IF(ISBLANK(Table1[[#This Row],[Tipo de Servicio]]),"",Caratula!$D$16) -> TAMAULIPAS SUR-VER NTE | C2: REFACCIONES - MAQUINA HIELO | D2: =_xlfn.XLOOKUP(Table5[[#This Row],[SelGZ]]&Table5[[#This Row],[Equipo]],CatPEP!A:A,CatPEP!C:C,"") -> M/MXCM/26/CG1J/C2/815/03 | E2: =_xlfn.XLOOKUP(Table5[[#This Row],[PEP]],CatPEP!C:C,CatPEP!D:D,"") -> MTTO MAQUINA HIELO | F2: FILTROS | G2: 2 | H2: 266 | I2: =Table5[[#This Row],[Precio Unitario]]*Table5[[#This Row],[Cantidad]] -> 532

Sheet Resumen para pago
A1: Aviso | B1: (blank)
A3: Sum of Total
A4: Proveedor | B4: GZ | C4: Periodo | D4: Tipo de Servicio | E4: PEP | F4: Nombre el PEP | G4: Total
A5: 0 | B5: TAMAULIPAS SUR-VER NTE | C5: S1926 | D5: INSTALACION - ENFRIADOR | E5: M/MXCM/26/CG1J/C2/815/01 | F5: MOVIMIENTOS | G5: 130
A6: 0 | B6: TAMAULIPAS SUR-VER NTE | C6: S1926 | D6: MTTO CORRECTIVO RUTA - BARRIL | E6: M/MXCM/26/CG1J/C2/815/02 | F6: MTTO BARRIL | G6: 0
A7: 0 | B7: TAMAULIPAS SUR-VER NTE | C7: S1926 | D7: COMPRA TANQUE CO2 - BARRIL | G7: 0
A8: 0 | B8: TAMAULIPAS SUR-VER NTE | C8: S1926 | D8: FLETE MOV GZ A GZ - ENFRIADOR | E8: M/MXCM/26/GA6B/C6/815/03 | F8: MOVIMIENTOS FLETES NAC | G8: 0
A9: 0 | B9: TAMAULIPAS SUR-VER NTE | C9: S1926 | D9: FLETES-TALLER - MOVIMIENTOS | E9: M/MXCM/26/CG1J/C2/815/01 | F9: MOVIMIENTOS | G9: 0
A10: Grand Total | G10: 130

Sheet Catalogo
A1: Tipo de Servicio | B1: Column1 | C1: Servicio | D1: Tipo de Equipo | E1: Tipo de Servicio | G1: Fecha | H1: Semana | J1: Año | K1: Semana | L1: Periodo | M1: Inicio | N1: Fin | P1: GZ
A2: MTTO CORRECTIVO RUTA | B2: Mtto | C2: MTTO CORRECTIVO RUTA | D2: ENFRIADOR | E2: =Table2[[#This Row],[Servicio]]&" - "&Table2[[#This Row],[Tipo de Equipo]] -> MTTO CORRECTIVO RUTA - ENFRIADOR | G2: 45658 | H2: 52 | J2: 2025 | K2: 52 | L2: ="S"&TEXT(K2,"00")&RIGHT(J2,2) -> S5225 | M2: 46017 | N2: 46023 | P2: AGS-ZAC-SLP
A3: MTTO CORRECTIVO PISO | B3: Mtto | C3: MTTO CORRECTIVO RUTA | D3: MAQUINA HIELO | E3: =Table2[[#This Row],[Servicio]]&" - "&Table2[[#This Row],[Tipo de Equipo]] -> MTTO CORRECTIVO RUTA - MAQUINA HIELO | G3: 46024 | H3: =_xlfn.ISOWEEKNUM(G3) -> 1 | J3: 2026 | K3: 1 | L3: ="S"&TEXT(K3,"00")&RIGHT(J3,2) -> S0126 | M3: 46024 | N3: 46027 | P3: BCN
A4: MTTO PREVENTIVO RUTA | B4: Mtto | C4: MTTO CORRECTIVO RUTA | D4: BARRIL | E4: =Table2[[#This Row],[Servicio]]&" - "&Table2[[#This Row],[Tipo de Equipo]] -> MTTO CORRECTIVO RUTA - BARRIL | G4: 46025 | H4: =_xlfn.ISOWEEKNUM(G4) -> 1 | J4: 2026 | K4: 2 | L4: ="S"&TEXT(K4,"00")&RIGHT(J4,2) -> S0226 | M4: 46028 | N4: 46034 | P4: BCS
A5: INSTALACION | B5: Mtto | C5: MTTO CORRECTIVO RUTA | D5: CUARTO FRIO | E5: =Table2[[#This Row],[Servicio]]&" - "&Table2[[#This Row],[Tipo de Equipo]] -> MTTO CORRECTIVO RUTA - CUARTO FRIO | G5: 46026 | H5: =_xlfn.ISOWEEKNUM(G5) -> 1 | J5: 2026 | K5: 3 | L5: ="S"&TEXT(K5,"00")&RIGHT(J5,2) -> S0326 | M5: 46035 | N5: 46041 | P5: CHIHUAHUA
A6: RETIRO | B6: Mtto | C6: MTTO CORRECTIVO PISO | D6: ENFRIADOR | E6: =Table2[[#This Row],[Servicio]]&" - "&Table2[[#This Row],[Tipo de Equipo]] -> MTTO CORRECTIVO PISO - ENFRIADOR | G6: 46027 | H6: =_xlfn.ISOWEEKNUM(G6) -> 2 | J6: 2026 | K6: 4 | L6: ="S"&TEXT(K6,"00")&RIGHT(J6,2) -> S0426 | M6: 46042 | N6: 46048 | P6: COAHUILA
B7: Mtto | C7: MTTO CORRECTIVO PISO | D7: MAQUINA HIELO | E7: =Table2[[#This Row],[Servicio]]&" - "&Table2[[#This Row],[Tipo de Equipo]] -> MTTO CORRECTIVO PISO - MAQUINA HIELO | G7: 46028 | H7: =_xlfn.ISOWEEKNUM(G7) -> 2 | J7: 2026 | K7: 5 | L7: ="S"&TEXT(K7,"00")&RIGHT(J7,2) -> S0526 | M7: 46049 | N7: 46055 | P7: DURANGO
B8: Mtto | C8: MTTO CORRECTIVO PISO | D8: BARRIL | E8: =Table2[[#This Row],[Servicio]]&" - "&Table2[[#This Row],[Tipo de Equipo]] -> MTTO CORRECTIVO PISO - BARRIL | G8: 46029 | H8: =_xlfn.ISOWEEKNUM(G8) -> 2 | J8: 2026 | K8: 6 | L8: ="S"&TEXT(K8,"00")&RIGHT(J8,2) -> S0626 | M8: 46056 | N8: 46062 | P8: EDO DE MEXICO
B9: Mtto | C9: MTTO PREVENTIVO RUTA | D9: MAQUINA HIELO | E9: =Table2[[#This Row],[Servicio]]&" - "&Table2[[#This Row],[Tipo de Equipo]] -> MTTO PREVENTIVO RUTA - MAQUINA HIELO | G9: 46030 | H9: =_xlfn.ISOWEEKNUM(G9) -> 2 | J9: 2026 | K9: 7 | L9: ="S"&TEXT(K9,"00")&RIGHT(J9,2) -> S0726 | M9: 46063 | N9: 46069 | P9: FRANQUICIA CHIAPAS
B10: Mtto | C10: MTTO PREVENTIVO RUTA | D10: BARRIL | E10: =Table2[[#This Row],[Servicio]]&" - "&Table2[[#This Row],[Tipo de Equipo]] -> MTTO PREVENTIVO RUTA - BARRIL | G10: 46031 | H10: =_xlfn.ISOWEEKNUM(G10) -> 2 | J10: 2026 | K10: 8 | L10: ="S"&TEXT(K10,"00")&RIGHT(J10,2) -> S0826 | M10: 46070 | N10: 46076 | P10: QRO-GTO
B11: Mtto | C11: MTTO PREVENTIVO RUTA | D11: CUARTO FRIO | E11: =Table2[[#This Row],[Servicio]]&" - "&Table2[[#This Row],[Tipo de Equipo]] -> MTTO PREVENTIVO RUTA - CUARTO FRIO | G11: 46032 | H11: =_xlfn.ISOWEEKNUM(G11) -> 2 | J11: 2026 | K11: 9 | L11: ="S"&TEXT(K11,"00")&RIGHT(J11,2) -> S0926 | M11: 46077 | N11: 46083 | P11: GRO-MOR
B12: Movimientos | C12: INSTALACION | D12: ENFRIADOR | E12: =Table2[[#This Row],[Servicio]]&" - "&Table2[[#This Row],[Tipo de Equipo]] -> INSTALACION - ENFRIADOR | G12: 46033 | H12: =_xlfn.ISOWEEKNUM(G12) -> 2 | J12: 2026 | K12: 10 | L12: ="S"&TEXT(K12,"00")&RIGHT(J12,2) -> S1026 | M12: 46084 | N12: 46090 | P12: HIDALGO
B13: Movimientos | C13: INSTALACION | D13: MAQUINA HIELO | E13: =Table2[[#This Row],[Servicio]]&" - "&Table2[[#This Row],[Tipo de Equipo]] -> INSTALACION - MAQUINA HIELO | G13: 46034 | H13: =_xlfn.ISOWEEKNUM(G13) -> 3 | J13: 2026 | K13: 11 | L13: ="S"&TEXT(K13,"00")&RIGHT(J13,2) -> S1126 | M13: 46091 | N13: 46097 | P13: JALISCO-COLIMA-NAYARIT
B14: Movimientos | C14: INSTALACION | D14: BARRIL | E14: =Table2[[#This Row],[Servicio]]&" - "&Table2[[#This Row],[Tipo de Equipo]] -> INSTALACION - BARRIL | G14: 46035 | H14: =_xlfn.ISOWEEKNUM(G14) -> 3 | J14: 2026 | K14: 12 | L14: ="S"&TEXT(K14,"00")&RIGHT(J14,2) -> S1226 | M14: 46098 | N14: 46104 | P14: JUAREZ
B15: Movimientos | C15: INSTALACION | D15: CUARTO FRIO | E15: =Table2[[#This Row],[Servicio]]&" - "&Table2[[#This Row],[Tipo de Equipo]] -> INSTALACION - CUARTO FRIO | G15: 46036 | H15: =_xlfn.ISOWEEKNUM(G15) -> 3 | J15: 2026 | K15: 13 | L15: ="S"&TEXT(K15,"00")&RIGHT(J15,2) -> S1326 | M15: 46105 | N15: 46111 | P15: MICHOACAN
B16: Movimientos | C16: RETIRO | D16: ENFRIADOR | E16: =Table2[[#This Row],[Servicio]]&" - "&Table2[[#This Row],[Tipo de Equipo]] -> RETIRO - ENFRIADOR | G16: 46037 | H16: =_xlfn.ISOWEEKNUM(G16) -> 3 | J16: 2026 | K16: 14 | L16: ="S"&TEXT(K16,"00")&RIGHT(J16,2) -> S1426 | M16: 46112 | N16: 46118 | P16: NUEVO LEON
B17: Movimientos | C17: RETIRO | D17: MAQUINA HIELO | E17: =Table2[[#This Row],[Servicio]]&" - "&Table2[[#This Row],[Tipo de Equipo]] -> RETIRO - MAQUINA HIELO | G17: 46038 | H17: =_xlfn.ISOWEEKNUM(G17) -> 3 | J17: 2026 | K17: 15 | L17: ="S"&TEXT(K17,"00")&RIGHT(J17,2) -> S1526 | M17: 46119 | N17: 46125 | P17: OAXACA
B18: Movimientos | C18: RETIRO | D18: BARRIL | E18: =Table2[[#This Row],[Servicio]]&" - "&Table2[[#This Row],[Tipo de Equipo]] -> RETIRO - BARRIL | G18: 46039 | H18: =_xlfn.ISOWEEKNUM(G18) -> 3 | J18: 2026 | K18: 16 | L18: ="S"&TEXT(K18,"00")&RIGHT(J18,2) -> S1626 | M18: 46126 | N18: 46132 | P18: PUEBLA-TLAXCALA
... B23: Mtto | C23: FLETE MOV GZ A GZ | D23: ENFRIADOR | E23: =Table2[[#This Row],[Servicio]]&" - "&Table2[[#This Row],[Tipo de Equipo]] -> FLETE MOV GZ A GZ - ENFRIADOR | G23: 46044 | H23: =_xlfn.ISOWEEKNUM(G23) -> 4 | J23: 2026 | K23: 21 | L23: ="S"&TEXT(K23,"00")&RIGHT(J23,2) -> S2126 | M23: 46161 | N23: 46167 | P23: TAMAULIPAS NORTE
C24: FLETE MOV GZ A GZ | D24: MAQUINA HIELO | E24: =Table2[[#This Row],[Servicio]]&" - "&Table2[[#This Row],[Tipo de Equipo]] -> FLETE MOV GZ A GZ - MAQUINA HIELO | G24: 46045 | H24: =_xlfn.ISOWEEKNUM(G24) -> 4 | J24: 2026 | K24: 22 | L24: ="S"&TEXT(K24,"00")&RIGHT(J24,2) -> S2226 | M24: 46168 | N24: 46174 | P24: TAMAULIPAS SUR-VER NTE
C25: FLETE MOV GZ A GZ | D25: BARRIL | E25: =Table2[[#This Row],[Servicio]]&" - "&Table2[[#This Row],[Tipo de Equipo]] -> FLETE MOV GZ A GZ - BARRIL | G25: 46046 | H25: =_xlfn.ISOWEEKNUM(G25) -> 4 | J25: 2026 | K25: 23 | L25: ="S"&TEXT(K25,"00")&RIGHT(J25,2) -> S2326 | M25: 46175 | N25: 46181 | P25: VDM
C26: FLETE MOV GZ A GZ | D26: MOBILIARIO | E26: =Table2[[#This Row],[Servicio]]&" - "&Table2[[#This Row],[Tipo de Equipo]] -> FLETE MOV GZ A GZ - MOBILIARIO | G26: 46047 | H26: =_xlfn.ISOWEEKNUM(G26) -> 4 | J26: 2026 | K26: 24 | L26: ="S"&TEXT(K26,"00")&RIGHT(J26,2) -> S2426 | M26: 46182 | N26: 46188 | P26: VERACRUZ CENTRO
C27: FLETE MOV GZ A GZ | D27: VISIBILIDAD | E27: =Table2[[#This Row],[Servicio]]&" - "&Table2[[#This Row],[Tipo de Equipo]] -> FLETE MOV GZ A GZ - VISIBILIDAD | G27: 46048 | H27: =_xlfn.ISOWEEKNUM(G27) -> 5 | J27: 2026 | K27: 25 | L27: ="S"&TEXT(K27,"00")&RIGHT(J27,2) -> S2526 | M27: 46189 | N27: 46195 | P27: YUCAM
C28: FLETE MOV CEDIS A CEDIS | D28: ENFRIADOR | E28: =Table2[[#This Row],[Servicio]]&" - "&Table2[[#This Row],[Tipo de Equipo]] -> FLETE MOV CEDIS A CEDIS - ENFRIADOR | G28: 46049 | H28: =_xlfn.ISOWEEKNUM(G28) -> 5 | J28: 2026 | K28: 26 | L28: ="S"&TEXT(K28,"00")&RIGHT(J28,2) -> S2626 | M28: 46196 | N28: 46202
C29: FLETE MOV CEDIS A CEDIS | D29: MAQUINA HIELO | E29: =Table2[[#This Row],[Servicio]]&" - "&Table2[[#This Row],[Tipo de Equipo]] -> FLETE MOV CEDIS A CEDIS - MAQUINA HIELO | G29: 46050 | H29: =_xlfn.ISOWEEKNUM(G29) -> 5 | J29: 2026 | K29: 27 | L29: ="S"&TEXT(K29,"00")&RIGHT(J29,2) -> S2726 | M29: 46203 | N29: 46209
A30: Servicio | C30: FLETE MOV CEDIS A CEDIS | D30: BARRIL | E30: =Table2[[#This Row],[Servicio]]&" - "&Table2[[#This Row],[Tipo de Equipo]] -> FLETE MOV CEDIS A CEDIS - BARRIL | G30: 46051 | H30: =_xlfn.ISOWEEKNUM(G30) -> 5 | J30: 2026 | K30: 28 | L30: ="S"&TEXT(K30,"00")&RIGHT(J30,2) -> S2826 | M30: 46210 | N30: 46216
A31: REFACCIONES - ENFRIADOR | C31: FLETE MOV CEDIS A CEDIS | D31: MOBILIARIO | E31: =Table2[[#This Row],[Servicio]]&" - "&Table2[[#This Row],[Tipo de Equipo]] -> FLETE MOV CEDIS A CEDIS - MOBILIARIO | G31: 46052 | H31: =_xlfn.ISOWEEKNUM(G31) -> 5 | J31: 2026 | K31: 29 | L31: ="S"&TEXT(K31,"00")&RIGHT(J31,2) -> S2926 | M31: 46217 | N31: 46223
A32: REFACCIONES - MAQUINA HIELO | C32: FLETE MOV CEDIS A CEDIS | D32: VISIBILIDAD | E32: =Table2[[#This Row],[Servicio]]&" - "&Table2[[#This Row],[Tipo de Equipo]] -> FLETE MOV CEDIS A CEDIS - VISIBILIDAD | G32: 46053 | H32: =_xlfn.ISOWEEKNUM(G32) -> 5 | J32: 2026 | K32: 30 | L32: ="S"&TEXT(K32,"00")&RIGHT(J32,2) -> S3026 | M32: 46224 | N32: 46230
A33: REFACCIONES - BARRIL | C33: DOOR TO DOOR | D33: ALMACENAMIENTO | E33: =Table2[[#This Row],[Servicio]]&" - "&Table2[[#This Row],[Tipo de Equipo]] -> DOOR TO DOOR - ALMACENAMIENTO | G33: 46054 | H33: =_xlfn.ISOWEEKNUM(G33) -> 5 | J33: 2026 | K33: 31 | L33: ="S"&TEXT(K33,"00")&RIGHT(J33,2) -> S3126 | M33: 46231 | N33: 46237
A34: REFACCIONES - CUARTO FRIO | C34: REFACCIONES | D34: ENFRIADOR | E34: =Table2[[#This Row],[Servicio]]&" - "&Table2[[#This Row],[Tipo de Equipo]] -> REFACCIONES - ENFRIADOR | G34: 46055 | H34: =_xlfn.ISOWEEKNUM(G34) -> 6 | J34: 2026 | K34: 32 | L34: ="S"&TEXT(K34,"00")&RIGHT(J34,2) -> S3226 | M34: 46238 | N34: 46244
C35: REFACCIONES | D35: MAQUINA HIELO | E35: =Table2[[#This Row],[Servicio]]&" - "&Table2[[#This Row],[Tipo de Equipo]] -> REFACCIONES - MAQUINA HIELO | G35: 46056 | H35: =_xlfn.ISOWEEKNUM(G35) -> 6 | J35: 2026 | K35: 33 | L35: ="S"&TEXT(K35,"00")&RIGHT(J35,2) -> S3326 | M35: 46245 | N35: 46251
C36: REFACCIONES | D36: BARRIL | E36: =Table2[[#This Row],[Servicio]]&" - "&Table2[[#This Row],[Tipo de Equipo]] -> REFACCIONES - BARRIL | G36: 46057 | H36: =_xlfn.ISOWEEKNUM(G36) -> 6 | J36: 2026 | K36: 34 | L36: ="S"&TEXT(K36,"00")&RIGHT(J36,2) -> S3426 | M36: 46252 | N36: 46258
C37: REFACCIONES | D37: CUARTO FRIO | E37: =Table2[[#This Row],[Servicio]]&" - "&Table2[[#This Row],[Tipo de Equipo]] -> REFACCIONES - CUARTO FRIO | G37: 46058 | H37: =_xlfn.ISOWEEKNUM(G37) -> 6 | J37: 2026 | K37: 35 | L37: ="S"&TEXT(K37,"00")&RIGHT(J37,2) -> S3526 | M37: 46259 | N37: 46265
C38: COMPRA TANQUE CO2 | D38: BARRIL | E38: =Table2[[#This Row],[Servicio]]&" - "&Table2[[#This Row],[Tipo de Equipo]] -> COMPRA TANQUE CO2 - BARRIL | G38: 46059 | H38: =_xlfn.ISOWEEKNUM(G38) -> 6 | J38: 2026 | K38: 36 | L38: ="S"&TEXT(K38,"00")&RIGHT(J38,2) -> S3626 | M38: 46266 | N38: 46272
C39: INST ENFRIADOR SIX BASE | D39: ENFRIADOR | E39: =Table2[[#This Row],[Servicio]]&" - "&Table2[[#This Row],[Tipo de Equipo]] -> INST ENFRIADOR SIX BASE - ENFRIADOR | G39: 46060 | H39: =_xlfn.ISOWEEKNUM(G39) -> 6 | J39: 2026 | K39: 37 | L39: ="S"&TEXT(K39,"00")&RIGHT(J39,2) -> S3726 | M39: 46273 | N39: 46279
C40: INST MH SIX BASE | D40: MAQUINA HIELO | E40: =Table2[[#This Row],[Servicio]]&" - "&Table2[[#This Row],[Tipo de Equipo]] -> INST MH SIX BASE - MAQUINA HIELO | G40: 46061 | H40: =_xlfn.ISOWEEKNUM(G40) -> 6 | J40: 2026 | K40: 38 | L40: ="S"&TEXT(K40,"00")&RIGHT(J40,2) -> S3826 | M40: 46280 | N40: 46286
C41: INST-CC | D41: MOBILIARIO | E41: =Table2[[#This Row],[Servicio]]&" - "&Table2[[#This Row],[Tipo de Equipo]] -> INST-CC - MOBILIARIO | G41: 46062 | H41: =_xlfn.ISOWEEKNUM(G41) -> 7 | J41: 2026 | K41: 39 | L41: ="S"&TEXT(K41,"00")&RIGHT(J41,2) -> S3926 | M41: 46287 | N41: 46293
C42: INST-CM | D42: MOBILIARIO | E42: =Table2[[#This Row],[Servicio]]&" - "&Table2[[#This Row],[Tipo de Equipo]] -> INST-CM - MOBILIARIO | G42: 46063 | H42: =_xlfn.ISOWEEKNUM(G42) -> 7 | J42: 2026 | K42: 40 | L42: ="S"&TEXT(K42,"00")&RIGHT(J42,2) -> S4026 | M42: 46294 | N42: 46300
C43: INST-PV | D43: MOBILIARIO | E43: =Table2[[#This Row],[Servicio]]&" - "&Table2[[#This Row],[Tipo de Equipo]] -> INST-PV - MOBILIARIO | G43: 46064 | H43: =_xlfn.ISOWEEKNUM(G43) -> 7 | J43: 2026 | K43: 41 | L43: ="S"&TEXT(K43,"00")&RIGHT(J43,2) -> S4126 | M43: 46301 | N43: 46307
C44: INST-SIX | D44: MOBILIARIO | E44: =Table2[[#This Row],[Servicio]]&" - "&Table2[[#This Row],[Tipo de Equipo]] -> INST-SIX - MOBILIARIO | G44: 46065 | H44: =_xlfn.ISOWEEKNUM(G44) -> 7 | J44: 2026 | K44: 42 | L44: ="S"&TEXT(K44,"00")&RIGHT(J44,2) -> S4226 | M44: 46308 | N44: 46314
...

Sheet CatPEP
A1: CONCAT | B1: GZ | C1: Objeto | D1: Iniciativa | E1: TIPO DE SERVICIO | F1: Tipo Servicio | G1: REGION
A2: =B2&Table4[[#This Row],[Tipo Servicio]] -> COAHUILACOMPRA TANQUE CO2 - BARRIL | B2: COAHUILA | C2: M/MXCM/26/CGC3/C2/815/01 | D2: BARRIL CO2 | F2: COMPRA TANQUE CO2 - BARRIL | G2: =_xlfn.XLOOKUP(Table4[[#This Row],[GZ]],'[1]BASE TRADE'!$R:$R,'[1]BASE TRADE'!$Q:$Q) -> 2. Northeast
A3: =B3&Table4[[#This Row],[Tipo Servicio]] -> COAHUILAMTTO CORRECTIVO RUTA - MAQUINA HIELO | B3: COAHUILA | C3: M/MXCM/26/CGC3/C2/815/02 | D3: MTTO MAQUINA HIELO | F3: MTTO CORRECTIVO RUTA - MAQUINA HIELO | G3: =_xlfn.XLOOKUP(Table4[[#This Row],[GZ]],'[1]BASE TRADE'!$R:$R,'[1]BASE TRADE'!$Q:$Q) -> 2. Northeast
A4: =B4&Table4[[#This Row],[Tipo Servicio]] -> COAHUILAMTTO CORRECTIVO RUTA - BARRIL | B4: COAHUILA | C4: M/MXCM/26/CGC3/C2/815/03 | D4: MTTO BARRIL | F4: MTTO CORRECTIVO RUTA - BARRIL | G4: =_xlfn.XLOOKUP(Table4[[#This Row],[GZ]],'[1]BASE TRADE'!$R:$R,'[1]BASE TRADE'!$Q:$Q) -> 2. Northeast
A5: =B5&Table4[[#This Row],[Tipo Servicio]] -> COAHUILAMTTO CORRECTIVO RUTA - ENFRIADOR | B5: COAHUILA | C5: M/MXCM/26/CGC3/C2/815/04 | D5: MTTO ENFRIADORES | E5: RUTA | F5: MTTO CORRECTIVO RUTA - ENFRIADOR | G5: =_xlfn.XLOOKUP(Table4[[#This Row],[GZ]],'[1]BASE TRADE'!$R:$R,'[1]BASE TRADE'!$Q:$Q) -> 2. Northeast
A6: =B6&Table4[[#This Row],[Tipo Servicio]] -> COAHUILAMTTO CORRECTIVO PISO - ENFRIADOR | B6: COAHUILA | C6: M/MXCM/26/CGC3/C2/815/04 | D6: MTTO ENFRIADORES | E6: PISO | F6: MTTO CORRECTIVO PISO - ENFRIADOR | G6: =_xlfn.XLOOKUP(Table4[[#This Row],[GZ]],'[1]BASE TRADE'!$R:$R,'[1]BASE TRADE'!$Q:$Q) -> 2. Northeast
A7: =B7&Table4[[#This Row],[Tipo Servicio]] -> COAHUILAINSTALACION - ENFRIADOR | B7: COAHUILA | C7: M/MXCM/26/CGC3/C2/815/05 | D7: MOVIMIENTOS | F7: INSTALACION - ENFRIADOR | G7: =_xlfn.XLOOKUP(Table4[[#This Row],[GZ]],'[1]BASE TRADE'!$R:$R,'[1]BASE TRADE'!$Q:$Q) -> 2. Northeast
A8: =B8&Table4[[#This Row],[Tipo Servicio]] -> JUAREZINSTALACION - ENFRIADOR | B8: JUAREZ | C8: M/MXCM/26/CC4D/C1/815/01 | D8: MOVIMIENTOS | F8: INSTALACION - ENFRIADOR | G8: 1. Northwest
A9: =B9&Table4[[#This Row],[Tipo Servicio]] -> JUAREZMTTO CORRECTIVO RUTA - BARRIL | B9: JUAREZ | C9: M/MXCM/26/CC4D/C1/815/02 | D9: MTTO BARRIL | F9: MTTO CORRECTIVO RUTA - BARRIL | G9: 1. Northwest
A10: =B10&Table4[[#This Row],[Tipo Servicio]] -> JUAREZMTTO CORRECTIVO RUTA - CUARTO FRIO | B10: JUAREZ | C10: M/MXCM/26/CC4D/C1/815/03 | D10: MTTO CUARTO FRÍO | F10: MTTO CORRECTIVO RUTA - CUARTO FRIO | G10: 1. Northwest
A11: =B11&Table4[[#This Row],[Tipo Servicio]] -> JUAREZMTTO CORRECTIVO RUTA - MAQUINA HIELO | B11: JUAREZ | C11: M/MXCM/26/CC4D/C1/815/04 | D11: MTTO MAQUINA HIELO | F11: MTTO CORRECTIVO RUTA - MAQUINA HIELO | G11: 1. Northwest
A12: =B12&Table4[[#This Row],[Tipo Servicio]] -> JUAREZMTTO CORRECTIVO RUTA - ENFRIADOR | B12: JUAREZ | C12: M/MXCM/26/CC4D/C1/815/05 | D12: MTTO ENFRIADORES | E12: RUTA | F12: MTTO CORRECTIVO RUTA - ENFRIADOR | G12: 1. Northwest
A13: =B13&Table4[[#This Row],[Tipo Servicio]] -> JUAREZMTTO CORRECTIVO PISO - ENFRIADOR | B13: JUAREZ | C13: M/MXCM/26/CC4D/C1/815/05 | D13: MTTO ENFRIADORES | E13: PISO | F13: MTTO CORRECTIVO PISO - ENFRIADOR | G13: 1. Northwest
A14: =B14&Table4[[#This Row],[Tipo Servicio]] -> BCSCOMPRA TANQUE CO2 - BARRIL | B14: BCS | C14: M/MXCM/26/CHO8/C1/815/01 | D14: BARRIL CO2 | F14: COMPRA TANQUE CO2 - BARRIL | G14: 1. Northwest
A15: =B15&Table4[[#This Row],[Tipo Servicio]] -> BCSMTTO CORRECTIVO RUTA - BARRIL | B15: BCS | C15: M/MXCM/26/CHO8/C1/815/02 | D15: MTTO BARRIL | F15: MTTO CORRECTIVO RUTA - BARRIL | G15: 1. Northwest
A16: =B16&Table4[[#This Row],[Tipo Servicio]] -> BCSMTTO CORRECTIVO RUTA - CUARTO FRIO | B16: BCS | C16: M/MXCM/26/CHO8/C1/815/03 | D16: MTTO CUARTO FRÍO | F16: MTTO CORRECTIVO RUTA - CUARTO FRIO | G16: 1. Northwest
A17: =B17&Table4[[#This Row],[Tipo Servicio]] -> BCSMTTO CORRECTIVO RUTA - MAQUINA HIELO | B17: BCS | C17: M/MXCM/26/CHO8/C1/815/04 | D17: MTTO MAQUINA HIELO | F17: MTTO CORRECTIVO RUTA - MAQUINA HIELO | G17: 1. Northwest
A18: =B18&Table4[[#This Row],[Tipo Servicio]] -> BCSMTTO CORRECTIVO RUTA - ENFRIADOR | B18: BCS | C18: M/MXCM/26/CHO8/C1/815/05 | D18: MTTO ENFRIADORES | E18: RUTA | F18: MTTO CORRECTIVO RUTA - ENFRIADOR | G18: 1. Northwest
A19: =B19&Table4[[#This Row],[Tipo Servicio]] -> BCSMTTO CORRECTIVO PISO - ENFRIADOR | B19: BCS | C19: M/MXCM/26/CHO8/C1/815/05 | D19: MTTO ENFRIADORES | E19: PISO | F19: MTTO CORRECTIVO PISO - ENFRIADOR | G19: 1. Northwest
A20: =B20&Table4[[#This Row],[Tipo Servicio]] -> BCSINSTALACION - ENFRIADOR | B20: BCS | C20: M/MXCM/26/CHO8/C1/815/06 | D20: MOVIMIENTOS | F20: INSTALACION - ENFRIADOR | G20: 1. Northwest
A21: =B21&Table4[[#This Row],[Tipo Servicio]] -> SONORAINSTALACION - ENFRIADOR | B21: SONORA | C21: M/MXCM/26/CCH7/C1/815/01 | D21: MOVIMIENTOS | F21: INSTALACION - ENFRIADOR | G21: =_xlfn.XLOOKUP(Table4[[#This Row],[GZ]],'[1]BASE TRADE'!$R:$R,'[1]BASE TRADE'!$Q:$Q) -> 1. Northwest
A22: =B22&Table4[[#This Row],[Tipo Servicio]] -> SONORACOMPRA TANQUE CO2 - BARRIL | B22: SONORA | C22: M/MXCM/26/CCH7/C1/815/02 | D22: BARRIL CO2 | F22: COMPRA TANQUE CO2 - BARRIL | G22: =_xlfn.XLOOKUP(Table4[[#This Row],[GZ]],'[1]BASE TRADE'!$R:$R,'[1]BASE TRADE'!$Q:$Q) -> 1. Northwest
A23: =B23&Table4[[#This Row],[Tipo Servicio]] -> SONORAMTTO CORRECTIVO RUTA - BARRIL | B23: SONORA | C23: M/MXCM/26/CCH7/C1/815/03 | D23: MTTO BARRIL | F23: MTTO CORRECTIVO RUTA - BARRIL | G23: =_xlfn.XLOOKUP(Table4[[#This Row],[GZ]],'[1]BASE TRADE'!$R:$R,'[1]BASE TRADE'!$Q:$Q) -> 1. Northwest
A24: =B24&Table4[[#This Row],[Tipo Servicio]] -> SONORAMTTO CORRECTIVO RUTA - CUARTO FRIO | B24: SONORA | C24: M/MXCM/26/CCH7/C1/815/04 | D24: MTTO CUARTO FRÍO | F24: MTTO CORRECTIVO RUTA - CUARTO FRIO | G24: =_xlfn.XLOOKUP(Table4[[#This Row],[GZ]],'[1]BASE TRADE'!$R:$R,'[1]BASE TRADE'!$Q:$Q) -> 1. Northwest
A25: =B25&Table4[[#This Row],[Tipo Servicio]] -> SONORAMTTO CORRECTIVO RUTA - MAQUINA HIELO | B25: SONORA | C25: M/MXCM/26/CCH7/C1/815/05 | D25: MTTO MAQUINA HIELO | F25: MTTO CORRECTIVO RUTA - MAQUINA HIELO | G25: =_xlfn.XLOOKUP(Table4[[#This Row],[GZ]],'[1]BASE TRADE'!$R:$R,'[1]BASE TRADE'!$Q:$Q) -> 1. Northwest
A26: =B26&Table4[[#This Row],[Tipo Servicio]] -> SONORAMTTO CORRECTIVO RUTA - ENFRIADOR | B26: SONORA | C26: M/MXCM/26/CCH7/C1/815/06 | D26: MTTO ENFRIADORES | E26: RUTA | F26: MTTO CORRECTIVO RUTA - ENFRIADOR | G26: =_xlfn.XLOOKUP(Table4[[#This Row],[GZ]],'[1]BASE TRADE'!$R:$R,'[1]BASE TRADE'!$Q:$Q) -> 1. Northwest
A27: =B27&Table4[[#This Row],[Tipo Servicio]] -> SONORAMTTO CORRECTIVO PISO - ENFRIADOR | B27: SONORA | C27: M/MXCM/26/CCH7/C1/815/06 | D27: MTTO ENFRIADORES | E27: PISO | F27: MTTO CORRECTIVO PISO - ENFRIADOR | G27: =_xlfn.XLOOKUP(Table4[[#This Row],[GZ]],'[1]BASE TRADE'!$R:$R,'[1]BASE TRADE'!$Q:$Q) -> 1. Northwest
A28: =B28&Table4[[#This Row],[Tipo Servicio]] -> CHIHUAHUACOMPRA TANQUE CO2 - BARRIL | B28: CHIHUAHUA | C28: M/MXCM/26/CC3L/C1/815/01 | D28: BARRIL CO2 | F28: COMPRA TANQUE CO2 - BARRIL | G28: =_xlfn.XLOOKUP(Table4[[#This Row],[GZ]],'[1]BASE TRADE'!$R:$R,'[1]BASE TRADE'!$Q:$Q) -> 1. Northwest
A29: =B29&Table4[[#This Row],[Tipo Servicio]] -> CHIHUAHUAMTTO CORRECTIVO RUTA - BARRIL | B29: CHIHUAHUA | C29: M/MXCM/26/CC3L/C1/815/02 | D29: MTTO BARRIL | F29: MTTO CORRECTIVO RUTA - BARRIL | G29: =_xlfn.XLOOKUP(Table4[[#This Row],[GZ]],'[1]BASE TRADE'!$R:$R,'[1]BASE TRADE'!$Q:$Q) -> 1. Northwest
A30: =B30&Table4[[#This Row],[Tipo Servicio]] -> CHIHUAHUAMTTO CORRECTIVO RUTA - CUARTO FRIO | B30: CHIHUAHUA | C30: M/MXCM/26/CC3L/C1/815/03 | D30: MTTO CUARTO FRÍO | F30: MTTO CORRECTIVO RUTA - CUARTO FRIO | G30: =_xlfn.XLOOKUP(Table4[[#This Row],[GZ]],'[1]BASE TRADE'!$R:$R,'[1]BASE TRADE'!$Q:$Q) -> 1. Northwest
A31: =B31&Table4[[#This Row],[Tipo Servicio]] -> CHIHUAHUAMTTO CORRECTIVO RUTA - MAQUINA HIELO | B31: CHIHUAHUA | C31: M/MXCM/26/CC3L/C1/815/04 | D31: MTTO MAQUINA HIELO | F31: MTTO CORRECTIVO RUTA - MAQUINA HIELO | G31: =_xlfn.XLOOKUP(Table4[[#This Row],[GZ]],'[1]BASE TRADE'!$R:$R,'[1]BASE TRADE'!$Q:$Q) -> 1. Northwest
A32: =B32&Table4[[#This Row],[Tipo Servicio]] -> CHIHUAHUAMTTO CORRECTIVO RUTA - ENFRIADOR | B32: CHIHUAHUA | C32: M/MXCM/26/CC3L/C1/815/05 | D32: MTTO ENFRIADORES | E32: RUTA | F32: MTTO CORRECTIVO RUTA - ENFRIADOR | G32: =_xlfn.XLOOKUP(Table4[[#This Row],[GZ]],'[1]BASE TRADE'!$R:$R,'[1]BASE TRADE'!$Q:$Q) -> 1. Northwest
A33: =B33&Table4[[#This Row],[Tipo Servicio]] -> CHIHUAHUAMTTO CORRECTIVO PISO - ENFRIADOR | B33: CHIHUAHUA | C33: M/MXCM/26/CC3L/C1/815/05 | D33: MTTO ENFRIADORES | E33: PISO | F33: MTTO CORRECTIVO PISO - ENFRIADOR | G33: =_xlfn.XLOOKUP(Table4[[#This Row],[GZ]],'[1]BASE TRADE'!$R:$R,'[1]BASE TRADE'!$Q:$Q) -> 1. Northwest
A34: =B34&Table4[[#This Row],[Tipo Servicio]] -> CHIHUAHUAINSTALACION - ENFRIADOR | B34: CHIHUAHUA | C34: M/MXCM/26/CC3L/C1/815/06 | D34: MOVIMIENTOS | F34: INSTALACION - ENFRIADOR | G34: =_xlfn.XLOOKUP(Table4[[#This Row],[GZ]],'[1]BASE TRADE'!$R:$R,'[1]BASE TRADE'!$Q:$Q) -> 1. Northwest
A35: =B35&Table4[[#This Row],[Tipo Servicio]] -> SINALOAINSTALACION - ENFRIADOR | B35: SINALOA | C35: M/MXCM/26/CCS3/C1/815/01 | D35: MOVIMIENTOS | F35: INSTALACION - ENFRIADOR | G35: =_xlfn.XLOOKUP(Table4[[#This Row],[GZ]],'[1]BASE TRADE'!$R:$R,'[1]BASE TRADE'!$Q:$Q) -> 1. Northwest
A36: =B36&Table4[[#This Row],[Tipo Servicio]] -> SINALOACOMPRA TANQUE CO2 - BARRIL | B36: SINALOA | C36: M/MXCM/26/CCS3/C1/815/02 | D36: BARRIL CO2 | F36: COMPRA TANQUE CO2 - BARRIL | G36: =_xlfn.XLOOKUP(Table4[[#This Row],[GZ]],'[1]BASE TRADE'!$R:$R,'[1]BASE TRADE'!$Q:$Q) -> 1. Northwest
A37: =B37&Table4[[#This Row],[Tipo Servicio]] -> SINALOAMTTO CORRECTIVO RUTA - BARRIL | B37: SINALOA | C37: M/MXCM/26/CCS3/C1/815/03 | D37: MTTO BARRIL | F37: MTTO CORRECTIVO RUTA - BARRIL | G37: =_xlfn.XLOOKUP(Table4[[#This Row],[GZ]],'[1]BASE TRADE'!$R:$R,'[1]BASE TRADE'!$Q:$Q) -> 1. Northwest
A38: =B38&Table4[[#This Row],[Tipo Servicio]] -> SINALOAMTTO CORRECTIVO RUTA - CUARTO FRIO | B38: SINALOA | C38: M/MXCM/26/CCS3/C1/815/04 | D38: MTTO CUARTO FRÍO | F38: MTTO CORRECTIVO RUTA - CUARTO FRIO | G38: =_xlfn.XLOOKUP(Table4[[#This Row],[GZ]],'[1]BASE TRADE'!$R:$R,'[1]BASE TRADE'!$Q:$Q) -> 1. Northwest
A39: =B39&Table4[[#This Row],[Tipo Servicio]] -> SINALOAMTTO CORRECTIVO RUTA - MAQUINA HIELO | B39: SINALOA | C39: M/MXCM/26/CCS3/C1/815/05 | D39: MTTO MAQUINA HIELO | F39: MTTO CORRECTIVO RUTA - MAQUINA HIELO | G39: =_xlfn.XLOOKUP(Table4[[#This Row],[GZ]],'[1]BASE TRADE'!$R:$R,'[1]BASE TRADE'!$Q:$Q) -> 1. Northwest
A40: =B40&Table4[[#This Row],[Tipo Servicio]] -> SINALOAMTTO CORRECTIVO RUTA - ENFRIADOR | B40: SINALOA | C40: M/MXCM/26/CCS3/C1/815/06 | D40: MTTO ENFRIADORES | E40: RUTA | F40: MTTO CORRECTIVO RUTA - ENFRIADOR | G40: =_xlfn.XLOOKUP(Table4[[#This Row],[GZ]],'[1]BASE TRADE'!$R:$R,'[1]BASE TRADE'!$Q:$Q) -> 1. Northwest
...

Sheet Sheet2
A1: Servicio | B1: Tipo de Equipo | C1: Tipo de Servicio | D1: Iniciativa
A2: MTTO CORRECTIVO RUTA | B2: ENFRIADOR | C2: =Table2[[#This Row],[Servicio]]&" - "&Table2[[#This Row],[Tipo de Equipo]] -> MTTO CORRECTIVO RUTA - ENFRIADOR | D2: MTTO ENFRIADORES
A3: MTTO CORRECTIVO RUTA | B3: MAQUINA HIELO | C3: =Table2[[#This Row],[Servicio]]&" - "&Table2[[#This Row],[Tipo de Equipo]] -> MTTO CORRECTIVO RUTA - MAQUINA HIELO | D3: MTTO MAQUINA HIELO
A4: MTTO CORRECTIVO RUTA | B4: BARRIL | C4: =Table2[[#This Row],[Servicio]]&" - "&Table2[[#This Row],[Tipo de Equipo]] -> MTTO CORRECTIVO RUTA - BARRIL | D4: MTTO BARRIL
A5: MTTO CORRECTIVO RUTA | B5: CUARTO FRIO | C5: =Table2[[#This Row],[Servicio]]&" - "&Table2[[#This Row],[Tipo de Equipo]] -> MTTO CORRECTIVO RUTA - CUARTO FRIO | D5: MTTO CUARTO FRÍO
A6: MTTO CORRECTIVO PISO | B6: ENFRIADOR | C6: =Table2[[#This Row],[Servicio]]&" - "&Table2[[#This Row],[Tipo de Equipo]] -> MTTO CORRECTIVO PISO - ENFRIADOR | D6: MTTO ENFRIADORES
A7: MTTO CORRECTIVO PISO | B7: MAQUINA HIELO | C7: =Table2[[#This Row],[Servicio]]&" - "&Table2[[#This Row],[Tipo de Equipo]] -> MTTO CORRECTIVO PISO - MAQUINA HIELO | D7: MTTO MAQUINA HIELO
A8: MTTO CORRECTIVO PISO | B8: BARRIL | C8: =Table2[[#This Row],[Servicio]]&" - "&Table2[[#This Row],[Tipo de Equipo]] -> MTTO CORRECTIVO PISO - BARRIL | D8: MTTO BARRIL
A9: MTTO PREVENTIVO RUTA | B9: MAQUINA HIELO | C9: =Table2[[#This Row],[Servicio]]&" - "&Table2[[#This Row],[Tipo de Equipo]] -> MTTO PREVENTIVO RUTA - MAQUINA HIELO | D9: MTTO MAQUINA HIELO
A10: MTTO PREVENTIVO RUTA | B10: BARRIL | C10: =Table2[[#This Row],[Servicio]]&" - "&Table2[[#This Row],[Tipo de Equipo]] -> MTTO PREVENTIVO RUTA - BARRIL | D10: MTTO BARRIL
A11: MTTO PREVENTIVO RUTA | B11: CUARTO FRIO | C11: =Table2[[#This Row],[Servicio]]&" - "&Table2[[#This Row],[Tipo de Equipo]] -> MTTO PREVENTIVO RUTA - CUARTO FRIO | D11: MTTO CUARTO FRÍO
A12: INSTALACION | B12: ENFRIADOR | C12: =Table2[[#This Row],[Servicio]]&" - "&Table2[[#This Row],[Tipo de Equipo]] -> INSTALACION - ENFRIADOR | D12: MOVIMIENTOS
A13: INSTALACION | B13: MAQUINA HIELO | C13: =Table2[[#This Row],[Servicio]]&" - "&Table2[[#This Row],[Tipo de Equipo]] -> INSTALACION - MAQUINA HIELO | D13: MOVIMIENTOS
... A35: INST MH SIX BASE | B35: MOBILIARIO | C35: =Table2[[#This Row],[Servicio]]&" - "&Table2[[#This Row],[Tipo de Equipo]] -> REFACCIONES - MAQUINA HIELO | D35: DESARROLLO FRIO
